Workbook

Sheet 説明
B2: 【名称】 | C2: 琉球諸語語彙用例調査票（RyuLex）
B3: 【バージョン】 | C3: バージョン：1.0（初期版）
C4: 更新日：2026-03-22
B6: 【作成者】 | C6: セリック・ケナン
C7: Celik, Kenan
B9: 【ライセンス】 | C9: 本調査票はMITライセンスの下で公開されている。
C10: 利用者は、本調査票を自由に利用、複製、改変および再配布することができる。
C11: ただし、本調査票に関する著作権表示および本ライセンス表示を保持する必要がある。
B13: 【本調査票について】 | C13: 本調査票は、琉球諸語の語彙および用例を体系的に収集することを目的として作成された語彙調査票である。
B15: 【出典および再構成について】 | C15: 本調査票は、調査項目および意味分野の設定において、平山輝男（1992）『現代日本語方言大辞典』（明治書院）所収の「全国方言基礎語彙調査項目」を出発点としつつ、
C16: 構成の再編成、項目の追加・削除、注記の付与、および用例文の新規作成を通じて再構成したものである。
C17: 特に、項目の追加・削除および用例文の新規作成については、琉球諸語の語彙体系に適合させるとともに、
C18: 琉球諸語の調査場面において自然な用例が得られるよう配慮して調整を行った。
C19: なお、動詞・形容詞の一部の項目の選定にあたっては、
C20: 国立国語研究所「日本の消滅危機言語・方言の記録とドキュメンテーションの作成」プロジェクト（2016）による
C21: 「基礎語彙調査票（1174項目）」も参考にした。
B23: 【例文について】 | C23: 例文1は、松倉昂平氏の作成した例文に基づき、同氏のご厚意により使用している。
C24: 例文2は、本調査票の作成過程において新たに作成したものである。
C25: 例文は参考として提示されているものであり、調査実施においては適宜調整して使用されることを想定している。
B27: 【同源語IDについて】 | C27: 一部の項目に対して、UniCog※（琉球諸語の同源語接続枠組）の同源語IDを付与している。
C28: 「n.d.」は、対応する同源語がUniCogに未登録であることを示す。
C29: 「-」は、表現的・複合的な項目など、同源語IDの付与が適切でない場合に用いている。
C31: なお、一部の項目について、UniCogに基づく祖語のアクセント類を付与している。
C32: 調査時にはアクセントクラスの予測の参考として用いることができる。
C34: 使用しているUniCogのバージョンは、『日琉言宝』（https://kikigengo.ninjal.ac.jp/nrdb/）で公開されている version 1.9（2026-03-08）に基づいている。
C36: ※セリック・ケナン、中澤光平、麻生玲子（2024）「琉球祖語の再建に向けた比較データ構築用の枠組提案（UniCog）」『国立国語研究所論集』26: 69-97
C37: https://doi.org/10.15084/0002000156
B39: 【項目の初期順】 | C39: 分野番号・調査順・項目読みに基づいて並べてある。
B41: 【研究資金】 | C41: 日本学術振興会科学研究費補助金（課題番号：24K16076）の助成を受けて行われた。
B43: 【引用方法】 | C43: 本調査票の利用にあたっては、出典を明記していただけると幸いである。
C45: 引用例
C46: セリック・ケナン（年）『琉球諸語語彙用例調査票（RyuLex）』Version X
C47: Celik, Kenan (Year). RyuLex Ryukyuan Lexical Elicitation Questionnaire. Version X

Sheet 調査票
C1: 項目ID | D1: 調査順 | E1: 分野番号 | F1: 分野 | G1: 項目番号（平山92） | H1: 品詞ID | I1: 品詞 | J1: 拍数 | K1: 項目表記 | L1: 項目読み | M1: 同源語ID | N1: 類 (pJ) | O1: 系列 (pR) | P1: 使用範囲 | Q1: 補足 | R1: 例文1 | S1: 例文2 | T1: 例文メモ
C2: 667 | D2: 1 | E2: 1 | F2: 天地・季候 | G2: 14 | H2: 1 | I2: 名 | J2: 4 | K2: てっぺん | L2: てっぺん | M2: n.d. | P2: 日琉
C3: 777 | D3: 1 | E3: 1 | F3: 天地・季候 | G3: 157 | H3: 3 | I3: 形 | J3: 5 | K3: 蒸し暑い | L3: むしあつい | M3: n.d. | P3: 日琉 | R3: どこへ行っても、蒸し暑くてしょうがない。
C4: 772 | D4: 1 | E4: 1 | F4: 天地・季候 | G4: 153 | H4: 3 | I4: 形 | J4: 3 | K4: 暗い | L4: くらい | M4: 暗.k.a | N4: i | O4: A | P4: 日琉 | R4: 暗くなるのが早くなりましたね。
C5: 616 | D5: 1 | E5: 1 | F5: 天地・季候 | G5: 66 | H5: 1 | I5: 名 | J5: 5 | K5: 稲光 | L5: いなびかり | M5: 稲光.i.n | P5: 日琉
C6: 622 | D6: 1 | E6: 1 | F6: 天地・季候 | G6: 30 | H6: 1 | I6: 名 | J6: 2 | K6: 陰・影 | L6: かげ | M6: 蔭.k.n | N6: 5 | O6: C | P6: 日琉 | Q6: 木の陰、日の当たらないところ／人の影 | R6: 暑いから、建物の影で休もう。
C7: 603 | D7: 1 | E7: 1 | F7: 天地・季候 | G7: 54 | H7: 1 | I7: 名 | J7: 2 | K7: 雨 | L7: あめ | M7: 雨.a.n | N7: 5 | O7: B | P7: 日琉 | R7: 雨に降られてずぶ濡れになった。 | S7: 午後から＜雨＞が降るから、傘を持って行ったほうがいいよ。
C8: 638 | D8: 1 | E8: 1 | F8: 天地・季候 | G8: 76 | H8: 1 | I8: 名 | J8: 2 | K8: 雲 | L8: くも | M8: 雲.k.n | N8: 3 | O8: B | P8: 日琉 | R8: 荒島岳に雲がかかっている。 | S8: 黒い＜雲＞が近づいてきたから、雨が降るかもしれない。
C9: 621 | D9: 1 | E9: 1 | F9: 天地・季候 | G9: 17 | H9: 1 | I9: 名 | J9: 2 | K9: 奥 | L9: おく | M9: 奥.u.n | P9: 日琉 | R9: 【家族へ】ざるが棚の奥にあるんだけど、手が届かない。
C10: 701 | D10: 1 | E10: 1 | F10: 天地・季候 | G10: 166;143 | H10: 1 | I10: 名 | J10: 2 | K10: 横 | L10: よこ | M10: 横.j.n | N10: 1 | O10: A | P10: 日琉 | R10: 横を向くな。 | S10: 家の＜横＞に物置小屋を造った。
C11: 620 | D11: 1 | E11: 1 | F11: 天地・季候 | G11: 132 | H11: 1 | I11: 名 | J11: 2 | K11: 沖 | L11: おき | M11: 沖.u.n | P11: 日琉 | R11: 沖に網を仕掛ける。
C12: 650 | D12: 1 | E12: 1 | F12: 天地・季候 | G12: 13 | H12: 1 | I12: 名 | J12: 2 | K12: 下 | L12: しも | M12: 下.s.n.3 | O12: A | P12: 日琉 | Q12: 川の下流／方向としての下／上座に対する下 | R12: 下の方から上がってくる。 | S12: 先生を〈下（しも）〉に座らすなよ。
C13: 674 | D13: 1 | E13: 1 | F13: 天地・季候 | G13: 2 | H13: 1 | I13: 名 | J13: 2 | K13: 夏 | L13: なつ | M13: 夏.n.n | N13: 2 | O13: A | P13: 日琉 | S13: ＜夏＞になると、毎日海で泳いだものだ。
C14: 685 | D14: 1 | E14: 1 | F14: 天地・季候 | G14: 45;109 | H14: 1 | I14: 名 | J14: 1 | K14: 火 | L14: ひ | M14: 火.p.n | N14: 3 | O14: B | P14: 日琉 | R14: 火が消えてしまった。 | S14: ろうそくに＜火＞をつけると、少し明るくなった。
C15: 618 | D15: 1 | E15: 1 | F15: 天地・季候 | G15: 131 | H15: 1 | I15: 名 | J15: 2 | K15: 海 | L15: うみ | M15: 海.u.n | N15: 4 | O15: C | P15: 日琉 | R15: 海を見たことがない。 | S15: ＜海＞に潜ると、小さい魚がたくさん泳いでいた。
C16: 623 | D16: 1 | E16: 1 | F16: 天地・季候 | G16: 112 | H16: 1 | I16: 名 | J16: 2 | K16: 崖 | L16: がけ | M16: 崖.g.n | P16: 日琉 | R16: 崖の上に家が建っている。
C17: 774 | D17: 1 | E17: 1 | F17: 天地・季候 | G17: 158 | H17: 3 | I17: 形 | J17: 3 | K17: 寒い | L17: さむい | M17: 寒.s.a | P17: 日琉 | R17: だんだん寒くなってきましたね。
C18: 629 | D18: 1 | E18: 1 | F18: 天地・季候 | G18: 135 | H18: 1 | I18: 名 | J18: 2 | K18: 岸 | L18: きし | M18: 岸.k.n | N18: 3 | P18: 日琉 | Q18: 水に接している陸地
C19: 617 | D19: 1 | E19: 1 | F19: 天地・季候 | G19: 39 | H19: 1 | I19: 名 | J19: 2 | K19: 岩 | L19: いわ | M19: 岩.i.n | N19: 2 | O19: A | P19: 日琉 | R19: 岩が崖の上から転がってきた。
C20: 628 | D20: 1 | E20: 1 | F20: 天地・季候 | G20: 6 | H20: 1 | I20: 名 | J20: 3 | K20: 気候 | L20: きこう | M20: n.d. | P20: 日
C21: 631 | D21: 1 | E21: 1 | F21: 天地・季候 | G21: 5 | H21: 1 | I21: 名 | J21: 3 | K21: 季節 | L21: きせつ | M21: n.d. | P21: 日琉
C22: 619 | D22: 1 | E22: 1 | F22: 天地・季候 | G22: 109 | H22: 1 | I22: 名 | J22: 2 | K22: 丘 | L22: おか | M22: n.d. | P22: 日琉 | S22: あの＜丘＞に登ると、近くの島が見える。
C23: 659 | D23: 1 | E23: 1 | F23: 天地・季候 | G23: 19 | H23: 1 | I23: 名 | J23: 2 | K23: 玉 | L23: たま | M23: 玉.t.n | N23: 3 | O23: B | P23: 日琉 | R23: 猫が球を転がして遊んでいる。
C24: 635 | D24: 1 | E24: 1 | F24: 天地・季候 | G24: 34 | H24: 1 | I24: 名 | J24: 2 | K24: 金 | L24: きん | M24: 金.k.n.3 | P24: 日琉 | S24: ＜金＞の指輪は高くて買えない。
C25: 636 | D25: 1 | E25: 1 | F25: 天地・季候 | G25: 35 | H25: 1 | I25: 名 | J25: 2 | K25: 銀 | L25: ぎん | M25: 銀.g.n | P25: 日琉 | R25: この皿は銀でできている。 | S25: ＜銀＞で作られた昔のかんざしだよ。
C26: 655 | D26: 1 | E26: 1 | F26: 天地・季候 | G26: 91 | H26: 1 | I26: 名 | J26: 2 | K26: 空 | L26: そら | M26: 空.s.n | N26: 4 | O26: C | P26: 日琉
C27: 653 | D27: 1 | E27: 1 | F27: 天地・季候 | G27: 15 | H27: 1 | I27: 名 | J27: 2 | K27: 隅 | L27: すみ | M27: 隅.s.n | N27: 4 | P27: 日琉 | R27: 隅にほこりが溜まっている。
C28: 637 | D28: 1 | E28: 1 | F28: 天地・季候 | G28: 161 | H28: 1 | I28: 名 | J28: 2 | K28: 屑 | L28: くず | M28: 屑.k.n | P28: 日琉 | Q28: 木屑／金屑（かなくず） | R28: 木を切ったくずが散らばっている。
C29: 601 | D29: 1 | E29: 1 | F29: 天地・季候 | G29: 23 | H29: 1 | I29: 名 | J29: 2 | K29: 穴 | L29: あな | M29: 穴.a.n | N29: 3 | O29: B | P29: 日琉 | Q29: 地面に掘った穴／障子に開いた穴 | R29: 穴を掘って埋めておけ。 | S29: ＜穴＞を掘ってごみを埋めた。
C30: 660 | D30: 1 | E30: 1 | F30: 天地・季候 | G30: 94;3 | H30: 1 | I30: 名 | J30: 2 | K30: 月 | L30: つき | M30: 月.t.n | N30: 3 | O30: B | P30: 日琉 | R30: 今日は月がきれいだね。 | S30: 今夜は＜月＞がとてもきれいに見える。
C31: 773 | D31: 1 | E31: 1 | F31: 天地・季候 | G31: 149 | H31: 3 | I31: 形 | J31: 4 | K31: 険しい | L31: けわしい | M31: n.d. | P31: 日琉 | R31: 険しい道だね。
C32: 680 | D32: 1 | E32: 1 | F32: 天地・季候 | G32: 163;41;44 | H32: 1 | I32: 名 | J32: 2 | K32: 糊 | L32: のり | M32: 糊.n.n | N32: 3 | P32: 日琉
C33: 688 | D33: 1 | E33: 1 | F33: 天地・季候 | G33: 29 | H33: 1 | I33: 名 | J33: 3 | K33: 光り | L33: ひかり | M33: 光.p.n | N33: 4 | O33: B/C | P33: 日琉 | R33: 光が差して明るくなった。
C34: 766 | D34: 1 | E34: 1 | F34: 天地・季候 | G34: 143;213 | H34: 2 | I34: 動 | J34: 3 | K34: 光る | L34: ひかる | M34: 光.p.v | N34: ii | O34: B | P34: 日琉
C35: 767 | D35: 1 | E35: 1 | F35: 天地・季候 | G35: 144 | H35: 2 | I35: 動 | J35: 2 | K35: 降る | L35: ふる | M35: 降.p.v | N35: ii | O35: B | P35: 日琉 | R35: 雨が降りそうだね。
C36: 652 | D36: 1 | E36: 1 | F36: 天地・季候 | G36: 40 | H36: 1 | I36: 名 | J36: 2 | K36: 砂 | L36: すな | M36: 砂.s.n | N36: 1 | O36: A | P36: 日琉 | R36: 砂が目に入った。 | S36: この白い＜砂＞はサンゴや貝からできている。
C37: 643 | D37: 1 | E37: 1 | F37: 天地・季候 | G37: 114 | H37: 1 | I37: 名 | J37: 2 | K37: 坂 | L37: さか | M37: 坂.s.n | N37: 3 | P37: 日琉 | R37: この辺りは坂が多いね。
C38: 699 | D38: 1 | E38: 1 | F38: 天地・季候 | G38: 108 | H38: 1 | I38: 名 | J38: 2 | K38: 山 | L38: やま | M38: 山.j.n | N38: 3 | O38: B | P38: 日琉 | S38: ＜山＞で道に迷わないように気をつけよう。
C39: 645 | D39: 1 | E39: 1 | F39: 天地・季候 | G39: 162 | H39: 1 | I39: 名 | J39: 4 | K39: 山頂 | L39: さんちょう | M39: n.d. | P39: 日琉 | Q39: 山のてっぺん | R39: ついに山頂に着いた！
C40: 600 | D40: 1 | E40: 1 | F40: 天地・季候 | G40: 3 | H40: 1 | I40: 名 | J40: 2 | K40: 秋 | L40: あき | M40: 秋.a.n | N40: 5 | P40: 日琉 | S40: ＜秋＞になって風がだいぶ涼しくなったね。
...

Sheet 構造記述
B1: 欄名 | C1: 内容
B2: 項目ID | C2: 調査項目の一意かつ安定したID。編集過程で項目を削除してもIDは振り直さないため、欠番が生じる場合がある。
B3: 調査順 | C3: 調査時の目安として設定した項目の提示順。
B4: 分野番号 | C4: 分野の番号。平山（1992）に準拠している。
B5: 分野 | C5: 分野の名称。分野18まで平山（1992）の区分を踏襲している。
B6: 項目番号（平山92） | C6: 当該項目が平山（1992）に含まれる場合の元の番号。
B7: 品詞ID | C7: 品詞のID。「品詞」シートを参照。
B8: 品詞 | C8: 品詞の略号。
B9: 拍数 | C9: 見出し語の拍数。
B10: 項目表記 | C10: 見出し語の表記。
B11: 項目読み | C11: 見出し語の読み。
B12: 同源語ID | C12: UniCog (version 1.9) に基づくの同源語ID
... B19: 例文メモ | C19: 例文に関するメモ。

Sheet 品詞一覧
B1: ID | C1: 品詞 | D1: 略号 | E1: 数
B2: 1 | C2: 名詞 | D2: 名 | E2: =COUNTIF(調査票!$H$2:$H$2940,品詞一覧!B2) -> 1694
B3: 2 | C3: 動詞 | D3: 動 | E3: =COUNTIF(調査票!$H$2:$H$2940,品詞一覧!B3) -> 591
B4: 3 | C4: 形容詞 | D4: 形 | E4: =COUNTIF(調査票!$H$2:$H$2940,品詞一覧!B4) -> 193
B5: 4 | C5: 文法的要素 | D5: 文 | E5: =COUNTIF(調査票!$H$2:$H$2940,品詞一覧!B5) -> 1
B6: 5 | C6: その他 | D6: 他 | E6: =COUNTIF(調査票!$H$2:$H$2940,品詞一覧!B6) -> 42
B7: 6 | C7: 連体詞 | D7: 連体 | E7: =COUNTIF(調査票!$H$2:$H$2940,品詞一覧!B7) -> 8
B8: 7 | C8: 副詞 | D8: 副 | E8: =COUNTIF(調査票!$H$2:$H$2940,品詞一覧!B8) -> 7

Sheet 分野一覧
A1: 分野番号 | B1: 分野 | C1: 項目数 | D1: 備考
A2: 1 | B2: 天地・季候 | C2: =COUNTIF(調査票!$E$2:$E$2986,分野一覧!A2) -> 169
A3: 2 | B3: 動物 | C3: =COUNTIF(調査票!$E$2:$E$2986,分野一覧!A3) -> 152
A4: 3 | B4: 植物 | C4: =COUNTIF(調査票!$E$2:$E$2986,分野一覧!A4) -> 172
A5: 4 | B5: 人体 | C5: =COUNTIF(調査票!$E$2:$E$2986,分野一覧!A5) -> 232
A6: 5 | B6: 衣 | C6: =COUNTIF(調査票!$E$2:$E$2986,分野一覧!A6) -> 135
A7: 6 | B7: 食 | C7: =COUNTIF(調査票!$E$2:$E$2986,分野一覧!A7) -> 179
A8: 7 | B8: 住居 | C8: =COUNTIF(調査票!$E$2:$E$2986,分野一覧!A8) -> 152
A9: 8 | B9: 民俗 | C9: =COUNTIF(調査票!$E$2:$E$2986,分野一覧!A9) -> 116
A10: 9 | B10: 遊戯 | C10: =COUNTIF(調査票!$E$2:$E$2986,分野一覧!A10) -> 57
A11: 10 | B11: 教育 | C11: =COUNTIF(調査票!$E$2:$E$2986,分野一覧!A11) -> 63
A12: 11 | B12: 人間関係 | C12: =COUNTIF(調査票!$E$2:$E$2986,分野一覧!A12) -> 95
A13: 12 | B13: 社会・交通 | C13: =COUNTIF(調査票!$E$2:$E$2986,分野一覧!A13) -> 143
... A19: 18 | B19: 助詞・助動詞・その他 | C19: =COUNTIF(調査票!$E$2:$E$2986,分野一覧!A19) -> 56
A20: 19 | B20: 地名 | C20: =COUNTIF(調査票!$E$2:$E$2986,分野一覧!A20) -> 7 | D20: 平山（1992）にはない
A21: 20 | B21: 干支 | C21: =COUNTIF(調査票!$E$2:$E$2986,分野一覧!A21) -> 30 | D21: 平山（1992）にはない
